Workbook

Sheet Modal Awal
A1: REKAP USAHA GABINETTE MS
A3: Pembelian Alat
A4: No | B4: Keterangan | C4: Jumlah | D4: Harga | E4: Total Harga
A5: 1 | B5: Meja Lipat | C5: 1 | D5: 173862 | E5: =D5*C5 -> 173862
A6: =A5+1 -> 2 | B6: Kursi Lipat | C6: 2 | D6: 93797 | E6: =D6*C6 -> 187594
A7: =A6+1 -> 3 | B7: Loyang 20x20 | C7: 2 | D7: 29685 | E7: =D7*C7 -> 59370
A8: =A7+1 -> 4 | B8: Loyang 20x20 | C8: 2 | D8: 10550 | E8: =D8*C8 -> 21100
A9: =A8+1 -> 5 | B9: Loyang 20x20 | C9: 3 | D9: 10906 | E9: =D9*C9 -> 32718
A10: =A9+1 -> 6 | B10: Loyang 20x20 | C10: 3 | D10: =49000/C10 -> 16333.333 | E10: =D10*C10 -> 49000
A11: =A10+1 -> 7 | B11: Coller Bag | C11: 1 | D11: 285600 | E11: =D11*C11 -> 285600
A12: =A11+1 -> 8 | B12: Ice Pack | C12: 5 | D12: 10300 | E12: =D12*C12 -> 51500
A13: =A12+1 -> 9 | B13: Banner | C13: 1 | D13: 75000 | E13: =D13*C13 -> 75000
A14: =A13+1 -> 10 | B14: Timbangan | C14: 1 | D14: 38800 | E14: =D14*C14 -> 38800
A15: =A14+1 -> 11 | B15: Aluminium Foil Box | C15: 2 | D15: 10350 | E15: =D15*C15 -> 20700
A16: =A15+1 -> 12 | B16: Mixer | C16: 1 | D16: 61300 | E16: =D16*C16 -> 61300
A17: =A16+1 -> 13 | B17: Payung | C17: 1 | D17: 42700 | E17: =D17*C17 -> 42700
A18: =A17+1 -> 14 | B18: Holder Payung | C18: 1 | D18: 69700 | E18: =D18*C18 -> 69700
A19: =A18+1 -> 15 | B19: Sewa Lapak di GOR | C19: 1 | D19: 50000 | E19: =D19*C19 -> 50000
A20: =A19+1 -> 16 | B20: Aluminium Foil | C20: 1 | D20: 36922 | E20: =D20*C20 -> 36922
A21: =A20+1 -> 17 | B21: Plastik Party | C21: 1 | D21: 18400 | E21: =D21*C21 -> 18400
A22: =A21+1 -> 18 | B22: Plastik Wrap | C22: 1 | D22: 4922 | E22: =D22*C22 -> 4922
... A25: =A24+1 -> 21 | B25: Sarung Tangan | C25: 1 | D25: 10500 | E25: =D25*C25 -> 10500
A26: =A25+1 -> 22 | E26: =D26*C26 -> 0
A27: =A26+1 -> 23 | E27: =D27*C27 -> 0
A28: TOTAL HARGA | E28: =sum(E5:E27) -> 1362188
A30: Pembelian Bahan Batch 1
A31: No | B31: Keterangan | C31: Jumlah | D31: Ukuran | E31: Harga | F31: Total Harga
A32: 1 | B32: Kis Whipping Cream | C32: 1 | D32: 900 gr | E32: 96492 | F32: =E32*C32 -> 96492
A33: =A32+1 -> 2 | B33: Pondan Whipping Cream | C33: 2 | D33: 200 gr | E33: 32500 | F33: =E33*C33 -> 65000
A34: =A33+1 -> 3 | B34: Gula Pasir | C34: 1 | D34: 1 kg | E34: 17700 | F34: =E34*C34 -> 17700
A35: =A34+1 -> 4 | B35: Chocho chips | C35: 1 | D35: 45 gr | E35: 4580 | F35: =E35*C35 -> 4580
A36: =A35+1 -> 5 | B36: Chocho chips | C36: 1 | D36: 100 gr | E36: 7500 | F36: =E36*C36 -> 7500
A37: =A36+1 -> 6 | B37: Pewarna Cokelat | C37: 1 | D37: 30 ml | E37: 4909 | F37: =E37*C37 -> 4909
A38: =A37+1 -> 7 | B38: Pewarna Hijau | C38: 1 | D38: 30 ml | E38: 5000 | F38: =E38*C38 -> 5000
A39: =A38+1 -> 8 | B39: Bubuk Coklat | C39: 1 | D39: 250 gr | E39: 14543 | F39: =E39*C39 -> 14543
A40: =A39+1 -> 9 | B40: Bubuk Coklat | C40: 1 | D40: 80 gr | E40: 26000 | F40: =E40*C40 -> 26000
A41: =A40+1 -> 10 | B41: Bubuk Matcha | C41: 1 | D41: 440 gr | E41: 65705 | F41: =E41*C41 -> 65705
A42: =A41+1 -> 11 | B42: Regal | C42: 1 | D42: 125 gr | E42: 12200 | F42: =E42*C42 -> 12200
A43: =A42+1 -> 12 | B43: Susu Full Cream Ultra Milk | C43: 3 | D43: 125 ml | E43: 3500 | F43: =E43*C43 -> 10500
A44: =A43+1 -> 13 | B44: Buah Strawberry | C44: 2 | D44: kecil | E44: 10000 | F44: =E44*C44 -> 20000
...

Sheet Belanja per Batch
A1: REKAP USAHA GABINETTE MS
A3: Pembelian Bahan Batch 2
A4: No | B4: Keterangan | C4: Jumlah | D4: Ukuran | E4: Harga | F4: Total Harga
A5: 1 | B5: Kis Whipping Cream | C5: 2 | D5: 300 gr | E5: 33000 | F5: =E5*C5 -> 66000
A6: =A5+1 -> 2 | B6: Pondan Whipping Cream | C6: 2 | D6: 100 gr | E6: 17500 | F6: =E6*C6 -> 35000
A7: =A6+1 -> 3 | B7: Pondan Whipping Cream | C7: 2 | D7: 200 gr | E7: 32500 | F7: =E7*C7 -> 65000
A8: =A7+1 -> 4 | B8: Haan Whipping Cream | C8: 1 | D8: 200 gr | E8: 36000 | F8: =E8*C8 -> 36000
A9: =A8+1 -> 5 | B9: Aluminium Foil | C9: 1 | D9: 30 cm x 7,6 m | E9: 25000 | F9: =E9*C9 -> 25000
A10: =A9+1 -> 6 | B10: Dairy SKM | C10: 1 | D10: 1 kg | E10: 26000 | F10: =E10*C10 -> 26000
A11: =A10+1 -> 7 | B11: Chocho Chips | C11: 1 | D11: 100 gr | E11: 9500 | F11: =E11*C11 -> 9500
A12: =A11+1 -> 8 | B12: Gabin | C12: 5 | E12: 6000 | F12: =E12*C12 -> 30000
A13: =A12+1 -> 9 | B13: Haan Whipping Cream | C13: 1 | D13: 200 gr | E13: 36000 | F13: =E13*C13 -> 36000
A14: =A13+1 -> 10 | B14: Gabin | C14: 1 | E14: 6500 | F14: =E14*C14 -> 6500
A15: =A14+1 -> 11 | B15: Aluminium Foil | C15: 1 | D15: 30 cm x 7,6 m | E15: 25000 | F15: =E15*C15 -> 25000
A17: TOTAL HARGA | F17: =sum(F5:F12) -> 292500
A19: Pembelian Bahan Batch 3
A20: No | B20: Keterangan | C20: Jumlah | D20: Ukuran | E20: Harga | F20: Total Harga
A21: 1 | B21: Kis Whipping Cream | C21: 2 | D21: 900 gr | E21: 96492 | F21: =E21*C21 -> 192984
A22: =A21+1 -> 2 | B22: Selai Strawberry | C22: 2 | D22: 250 gr | E22: 5614 | F22: =E22*C22 -> 11228
A23: =A22+1 -> 3 | B23: Choco Chip Elmer | C23: 1 | D23: 90 gr | E23: 8407 | F23: =E23*C23 -> 8407
A24: =A23+1 -> 4 | B24: Gabin | C24: 6 | E24: 6334 | F24: =E24*C24 -> 38004
A25: =A24+1 -> 5 | B25: Gorio Rio | C25: 1 | D25: 200 gr | E25: 9000 | F25: =E25*C25 -> 9000
A26: =A25+1 -> 6 | F26: =E26*C26 -> 0
A27: =A26+1 -> 7 | F27: =E27*C27 -> 0
A28: =A27+1 -> 8 | F28: =E28*C28 -> 0
A29: =A28+1 -> 9 | F29: =E29*C29 -> 0
A30: =A29+1 -> 10 | F30: =E30*C30 -> 0
A31: TOTAL HARGA | F31: =sum(F21:F30) -> 259623
A33: Pembelian Bahan Batch 4
A34: No | B34: Keterangan | C34: Jumlah | D34: Ukuran | E34: Harga | F34: Total Harga
A35: 1 | B35: Aluminium Foil | C35: 2 | D35: 30 cm x 10 m | E35: 21200 | F35: =E35*C35 -> 42400
A36: =A35+1 -> 2 | B36: Plastik Party | C36: 2 | D36: 10 x 30 cm | E36: 8200 | F36: =E36*C36 -> 16400
A37: =A36+1 -> 3 | B37: Haan Whipping Cream | C37: 1 | D37: 400 gr | E37: 30500 | F37: =E37*C37 -> 30500
A38: =A37+1 -> 4 | B38: Kis Whipping Cream | C38: 1 | D38: 900 gr | E38: 96492 | F38: =E38*C38 -> 96492
A39: =A38+1 -> 5 | B39: Bubuk Cokelat Van Houten | C39: 1 | D39: 40 gr | E39: 15050 | F39: =E39*C39 -> 15050
A40: =A39+1 -> 6 | B40: Plastik Kresek | C40: 1 | E40: 3000 | F40: =E40*C40 -> 3000
A41: =A40+1 -> 7 | F41: =E41*C41 -> 0
A42: =A41+1 -> 8 | F42: =E42*C42 -> 0
A43: =A42+1 -> 9 | F43: =E43*C43 -> 0
A44: =A43+1 -> 10 | F44: =E44*C44 -> 0
...

Sheet Resep Kiss
A1: TAKARAN BAHAN | J1: Tingkatan Net Profit: | K1: Cokelat
K2: Double Choco
A3: Varian Gabin | K3: Matcha
A4: No | B4: Varian | C4: Bahan | D4: Pemakaian 1 loyang | E4: Pemakaian 1 pcs | F4: Harga/pcs | K4: Strawberry
A5: 1 | B5: Matcha | C5: Whipping Cream | D5: 200 gr | E5: 22 gr | F5: 2358 | K5: Matcha Reo
C6: Gabin | D6: 18 pcs | E6: 2 pcs | F6: 465 | K6: Cookies & Cream
C7: Bubuk Matcha | D7: 10 gr | E7: 1.11 | F7: 166.5 | K7: Strawberry Matcha
C8: Susu SKM | D8: 90 gr | E8: 9 gr | F8: 234
C9: Alat Lain | F9: 500
C10: Tenaga | F10: 500
C11: =sum(F5:F10) -> 4223.5 | G11: 8000 | H11: =G11-C11 -> 3776.5 | I11: =H11*9 -> 33988.5
A12: 2 | B12: Cookies and Cream | C12: Whipping Cream | D12: 200 gr | E12: 22 gr | F12: 2358
C13: Gabin | D13: 18 pcs | E13: 2 pcs | F13: 465
C14: Oreo | D14: 59,5 gr | E14: 6,6 gr | F14: 499
C15: Susu SKM | D15: 90 gr | E15: 9 gr | F15: 234
C16: Alat Lain | F16: 500
C17: Tenaga | F17: 500
C18: =sum(F12:F17) -> 4556 | G18: 9000 | H18: =G18-C18 -> 4444 | I18: =H18*9 -> 39996
A19: 3 | B19: Cokelat | C19: Whipping Cream | D19: 200 gr | E19: 22 gr | F19: 2358
C20: Gabin | D20: 18 pcs | E20: 2 pcs | F20: 465
C21: Bubuk Cokelat | D21: 10 gr | E21: 1,1 gr | F21: 357.5
C22: Susu SKM | D22: 90 gr | E22: 9 gr | F22: 234
C23: Pewarna Cokelat | D23: 3 ml | E23: 0,3 ml | F23: 49
C24: Alat Lain | F24: 500
C25: Tenaga | F25: 500
C26: =sum(F19:F25) -> 4463.5 | G26: 8000 | H26: =G26-C26 -> 3536.5 | I26: =H26*9 -> 31828.5
A27: 4 | B27: Double Chocho | C27: Whipping Cream | D27: 200 gr | E27: 22 gr | F27: 2358
C28: Gabin | D28: 18 pcs | E28: 2 pcs | F28: 465
C29: Bubuk Cokelat | D29: 10 gr | E29: 1,1 gr | F29: 357.5
C30: Susu SKM | D30: 90 gr | E30: 9 gr | F30: 234
C31: Pewarna Cokelat | D31: 3 ml | E31: 0,3 ml | F31: 49
C32: Chocho Chips | D32: 90 gr | E32: 10 gr | F32: 935
C33: Alat Lain | F33: 500
C34: Tenaga | F34: 500
C35: =sum(F27:F34) -> 5398.5 | G35: 9000 | H35: =G35-C35 -> 3601.5 | I35: =H35*9 -> 32413.5
A36: 5 | B36: Matcha Reo | C36: Whipping Cream | D36: 200 gr | E36: 22 gr | F36: 2358
C37: Gabin | D37: 18 pcs | E37: 2 pcs | F37: 465
C38: Bubuk Matcha | D38: 10 gr | E38: 1.11 | F38: 166.5
C39: Susu SKM | D39: 90 gr | E39: 9 gr | F39: 234
C40: Oreo | D40: 59,5 gr | E40: 6,6 gr | F40: 499
...

Sheet Resep Pondan
A1: TAKARAN BAHAN
A3: Varian Gabin
A4: No | B4: Varian | C4: Bahan | D4: Pemakaian 1 loyang | E4: Pemakaian 1 pcs | F4: Harga/pcs
A5: 1 | B5: Matcha | C5: Whipping Cream | D5: 200 gr | E5: 22 gr | F5: 3607
C6: Gabin | D6: 18 pcs | E6: 2 pcs | F6: 465
C7: Bubuk Matcha | D7: 10 gr | E7: 1.11 | F7: 166.5
C8: Susu SKM | D8: 90 gr | E8: 9 gr | F8: 234
C9: Alat Lain | F9: 500
C10: Tenaga | F10: 500
C11: =sum(F5:F10) -> 5472.5 | G11: 8000 | H11: =G11-C11 -> 2527.5 | I11: =H11*9 -> 22747.5
A12: 2 | B12: Cookies and Cream | C12: Whipping Cream | D12: 200 gr | E12: 22 gr | F12: 3607
C13: Gabin | D13: 18 pcs | E13: 2 pcs | F13: 465
C14: Oreo | D14: 59,5 gr | E14: 6,6 gr | F14: 499
C15: Susu SKM | D15: 90 gr | E15: 9 gr | F15: 234
C16: Alat Lain | F16: 500
C17: Tenaga | F17: 500
C18: =sum(F12:F17) -> 5805 | G18: 9000 | H18: =G18-C18 -> 3195 | I18: =H18*9 -> 28755
A19: 3 | B19: Cokelat | C19: Whipping Cream | D19: 200 gr | E19: 22 gr | F19: 3607
C20: Gabin | D20: 18 pcs | E20: 2 pcs | F20: 465
C21: Bubuk Cokelat | D21: 10 gr | E21: 1,1 gr | F21: 357.5
C22: Susu SKM | D22: 90 gr | E22: 9 gr | F22: 234
C23: Pewarna Cokelat | D23: 3 ml | E23: 0,3 ml | F23: 49
C24: Alat Lain | F24: 500
C25: Tenaga | F25: 500
C26: =sum(F19:F25) -> 5712.5 | G26: 8000 | H26: =G26-C26 -> 2287.5 | I26: =H26*9 -> 20587.5
A27: 4 | B27: Double Chocho | C27: Whipping Cream | D27: 200 gr | E27: 22 gr | F27: 3607
C28: Gabin | D28: 18 pcs | E28: 2 pcs | F28: 465
C29: Bubuk Cokelat | D29: 10 gr | E29: 1,1 gr | F29: 357.5
C30: Susu SKM | D30: 90 gr | E30: 9 gr | F30: 234
C31: Pewarna Cokelat | D31: 3 ml | E31: 0,3 ml | F31: 49
C32: Chocho Chips | D32: 90 gr | E32: 10 gr | F32: 935
C33: Alat Lain | F33: 500
C34: Tenaga | F34: 500
C35: =sum(F27:F34) -> 6647.5 | G35: 9000 | H35: =G35-C35 -> 2352.5 | I35: =H35*9 -> 21172.5
A36: 5 | B36: Matcha Reo | C36: Whipping Cream | D36: 200 gr | E36: 22 gr | F36: 3607
C37: Gabin | D37: 18 pcs | E37: 2 pcs | F37: 465
C38: Bubuk Matcha | D38: 10 gr | E38: 1.11 | F38: 166.5
C39: Susu SKM | D39: 90 gr | E39: 9 gr | F39: 234
C40: Oreo | D40: 59,5 gr | E40: 6,6 gr | F40: 499
C41: Alat Lain | F41: 500
...

Sheet Resep Kiss+Haan
A1: TAKARAN BAHAN
A3: Varian Gabin
A4: No | B4: Varian | C4: Bahan | D4: Pemakaian 1 loyang | E4: Pemakaian 1 pcs | F4: Harga/pcs | K4: Keterangan:
A5: 1 | B5: Matcha | C5: Whipping Cream | D5: 200 gr | E5: 22 gr | F5: 2544 | K5: Haan 200 gr | L5: 36000
C6: Gabin | D6: 18 pcs | E6: 2 pcs | F6: 465 | K6: Kiss 900 gr | L6: 96492
C7: Bubuk Matcha | D7: 10 gr | E7: 1.11 | F7: 166.5
C8: Susu SKM | D8: 90 gr | E8: 9 gr | F8: 234 | K8: Resep
C9: Alat Lain | F9: 500 | K9: Haan 20 gr | L9: 3600
C10: Tenaga | F10: 500 | K10: Kiss 180 gr | L10: 19299
C11: =sum(F5:F10) -> 4409.5 | G11: 8000 | H11: =G11-C11 -> 3590.5 | I11: =H11*9 -> 32314.5 | L11: =sum(L9:L10)/9 -> 2544.3333
A12: 2 | B12: Cookies and Cream | C12: Whipping Cream | D12: 200 gr | E12: 22 gr | F12: 2544
C13: Gabin | D13: 18 pcs | E13: 2 pcs | F13: 465
C14: Gorio-Rio | D14: 60 gr | E14: 6,6 gr | F14: 297
C15: Susu SKM | D15: 90 gr | E15: 9 gr | F15: 234
C16: Alat Lain | F16: 500
C17: Tenaga | F17: 500
C18: =sum(F12:F17) -> 4540 | G18: 9000 | H18: =G18-C18 -> 4460 | I18: =H18*9 -> 40140
A19: 3 | B19: Cokelat | C19: Whipping Cream | D19: 200 gr | E19: 22 gr | F19: 2544
C20: Gabin | D20: 18 pcs | E20: 2 pcs | F20: 465
C21: Bubuk Cokelat | D21: 10 gr | E21: 1,1 gr | F21: 414
C22: Susu SKM | D22: 90 gr | E22: 9 gr | F22: 234
C23: Pewarna Cokelat | D23: 3 ml | E23: 0,3 ml | F23: 49
C24: Alat Lain | F24: 500
C25: Tenaga | F25: 500
C26: =sum(F19:F25) -> 4706 | G26: 8000 | H26: =G26-C26 -> 3294 | I26: =H26*9 -> 29646
A27: 4 | B27: Double Chocho | C27: Whipping Cream | D27: 200 gr | E27: 22 gr | F27: 2544
C28: Gabin | D28: 18 pcs | E28: 2 pcs | F28: 465
C29: Bubuk Cokelat | D29: 10 gr | E29: 1,1 gr | F29: 414
C30: Susu SKM | D30: 90 gr | E30: 9 gr | F30: 234
C31: Pewarna Cokelat | D31: 3 ml | E31: 0,3 ml | F31: 49
C32: Chocho Chips | D32: 80 gr | E32: 8,8 gr | F32: 822
C33: Alat Lain | F33: 500
C34: Tenaga | F34: 500
C35: =sum(F27:F34) -> 5528 | G35: 9000 | H35: =G35-C35 -> 3472 | I35: =H35*9 -> 31248
A36: 5 | B36: Matcha Reo | C36: Whipping Cream | D36: 200 gr | E36: 22 gr | F36: 2544
C37: Gabin | D37: 18 pcs | E37: 2 pcs | F37: 465
C38: Bubuk Matcha | D38: 10 gr | E38: 1.11 | F38: 166.5
C39: Susu SKM | D39: 90 gr | E39: 9 gr | F39: 234
C40: Gorio-Rio | D40: 60 gr | E40: 6,6 gr | F40: 297
C41: Alat Lain | F41: 500
...

Sheet Resep Kis+Haan+Whipking
A1: TAKARAN BAHAN
A3: Varian Gabin
A4: No | B4: Varian | C4: Bahan | D4: Pemakaian 1 loyang | E4: Pemakaian 1 pcs | F4: Harga/pcs | K4: Keterangan:
A5: 1 | B5: Matcha | C5: Whipping Cream | D5: 200 gr | E5: 22 gr | F5: 2697 | K5: Haan 200 gr | L5: 36000
C6: Gabin | D6: 18 pcs | E6: 2 pcs | F6: 465 | K6: Kis 900 gr | L6: 96492
C7: Bubuk Matcha | D7: 10 gr | E7: 1.11 | F7: 166.5 | K7: Whipking 200 gr | L7: 24500
C8: Susu SKM | D8: 105 gr | E8: 11,6 gr | F8: 301.6
C9: Alat Lain | F9: 500
C10: Tenaga | F10: 500 | K10: Resep
C11: =sum(F5:F10) -> 4630.1 | G11: 8000 | H11: =G11-C11 -> 3369.9 | I11: =H11*9 -> 30329.1 | K11: Haan 20 gr | L11: 3600
A12: 2 | B12: Cookies and Cream | C12: Whipping Cream | D12: 200 gr | E12: 22 gr | F12: 2697 | K12: Kis 90 gr | L12: 9650
C13: Gabin | D13: 18 pcs | E13: 2 pcs | F13: 465 | K13: Whipking 90 gr | L13: 11025
C14: Oreo | D14: 59,5 gr | E14: 6,6 gr | F14: 499 | L14: =sum(L11:L13) -> 24275 | M14: =L14/9 -> 2697.2222
C15: Susu SKM | D15: 105 gr | E15: 11,6 gr | F15: 301.6
C16: Alat Lain | F16: 500
C17: Tenaga | F17: 500
C18: =sum(F12:F17) -> 4962.6 | G18: 9000 | H18: =G18-C18 -> 4037.4 | I18: =H18*9 -> 36336.6
A19: 3 | B19: Cokelat | C19: Whipping Cream | D19: 200 gr | E19: 22 gr | F19: 2697
C20: Gabin | D20: 18 pcs | E20: 2 pcs | F20: 465
C21: Bubuk Cokelat | D21: 10 gr | E21: 1,1 gr | F21: 414
C22: Susu SKM | D22: 105 gr | E22: 11,6 gr | F22: 301.6
C23: Pewarna Cokelat | D23: 3 ml | E23: 0,3 ml | F23: 49
C24: Alat Lain | F24: 500
C25: Tenaga | F25: 500
C26: =sum(F19:F25) -> 4926.6 | G26: 8000 | H26: =G26-C26 -> 3073.4 | I26: =H26*9 -> 27660.6
A27: 4 | B27: Double Chocho | C27: Whipping Cream | D27: 200 gr | E27: 22 gr | F27: 2697
C28: Gabin | D28: 18 pcs | E28: 2 pcs | F28: 465
C29: Bubuk Cokelat | D29: 10 gr | E29: 1,1 gr | F29: 414
C30: Susu SKM | D30: 105 gr | E30: 11,6 gr | F30: 301.6
C31: Pewarna Cokelat | D31: 3 ml | E31: 0,3 ml | F31: 49
C32: Chocho Chips | D32: 80 gr | E32: 8,8 gr | F32: 822
C33: Alat Lain | F33: 500
C34: Tenaga | F34: 500
C35: =sum(F27:F34) -> 5748.6 | G35: 9000 | H35: =G35-C35 -> 3251.4 | I35: =H35*9 -> 29262.6
A36: 5 | B36: Matcha Reo | C36: Whipping Cream | D36: 200 gr | E36: 22 gr | F36: 2697
C37: Gabin | D37: 18 pcs | E37: 2 pcs | F37: 465
C38: Bubuk Matcha | D38: 10 gr | E38: 1.11 | F38: 166.5
C39: Susu SKM | D39: 105 gr | E39: 11,6 gr | F39: 301.6
C40: Oreo | D40: 59,5 gr | E40: 6,6 gr | F40: 499
C41: Alat Lain | F41: 500
...

Sheet Resep Fix
A1: TAKARAN BAHAN
A3: Varian Gabin
A4: No | B4: Varian | C4: Bahan | D4: Pemakaian 1 loyang | E4: Pemakaian 1 pcs | F4: Harga/pcs | G4: Harga Jual | H4: Laba/pcs | I4: Laba/loyang | K4: Keterangan:
A5: 1 | B5: Matcha | C5: Whipping Cream | D5: 200 gr | E5: 22 gr | F5: 2712 | K5: Haan 200 gr | L5: 36000
C6: Gabin | D6: 18 pcs | E6: 2 pcs | F6: 1170 | K6: Kis 900 gr | L6: 96492
C7: Bubuk Matcha | D7: 10 gr | E7: 1.11 | F7: 166.5 | K7: Whipking 200 gr | L7: 24500
C8: SKM Dairy | D8: 90 gr | E8: 10 gr | F8: 260
C9: Alat Lain | F9: 500
C10: Tenaga | F10: 500 | K10: Resep
C11: =sum(F5:F10) -> 5308.5 | G11: 9000 | H11: =G11-C11 -> 3691.5 | I11: =H11*9 -> 33223.5 | K11: Haan 25 gr | L11: 4500
A12: 2 | B12: Cokelat | C12: Whipping Cream | D12: 200 gr | E12: 22 gr | F12: 2712 | K12: Kis 100 gr | L12: 10722
C13: Gabin | D13: 18 pcs | E13: 2 pcs | F13: 1170 | K13: Whipking 75 gr | L13: 9188
C14: Bubuk Cokelat | D14: 10 gr | E14: 1,1 gr | F14: 414 | L14: =sum(L11:L13) -> 24410 | M14: =L14/9 -> 2712.2222
C15: SKM Enak | D15: 90 gr | E15: 10 gr | F15: 260
C16: Pewarna Cokelat | D16: 3 ml | E16: 0,3 ml | F16: 49
C17: Alat Lain | F17: 500
C18: Tenaga | F18: 500
C19: =sum(F12:F18) -> 5605 | G19: 9000 | H19: =G19-C19 -> 3395 | I19: =H19*9 -> 30555
A20: 3 | B20: Cookies and Cream | C20: Whipping Cream | D20: 200 gr | E20: 22 gr | F20: 2712
C21: Gabin | D21: 18 pcs | E21: 2 pcs | F21: 1170
C22: Oreo | D22: 52,5 gr | E22: 5,9 gr | F22: 441
C23: SKM Dairy | D23: 90 gr | E23: 10 gr | F23: 260
C24: Alat Lain | F24: 500
C25: Tenaga | F25: 500
C26: =sum(F20:F25) -> 5583 | G26: 10000 | H26: =G26-C26 -> 4417 | I26: =H26*9 -> 39753
A27: 4 | B27: Double Chocho | C27: Whipping Cream | D27: 200 gr | E27: 22 gr | F27: 2712
C28: Gabin | D28: 18 pcs | E28: 2 pcs | F28: 1170
C29: Bubuk Cokelat | D29: 10 gr | E29: 1,1 gr | F29: 414
C30: SKM Enak | D30: 90 gr | E30: 10 gr | F30: 260
C31: Pewarna Cokelat | D31: 3 ml | E31: 0,3 ml | F31: 49
C32: Chocho Chips | D32: 80 gr | E32: 8,8 gr | F32: 952
C33: Alat Lain | F33: 500
C34: Tenaga | F34: 500
C35: =sum(F27:F34) -> 6557 | G35: 10000 | H35: =G35-C35 -> 3443 | I35: =H35*9 -> 30987
A36: 5 | B36: Matcha Reo | C36: Whipping Cream | D36: 200 gr | E36: 22 gr | F36: 2712
C37: Gabin | D37: 18 pcs | E37: 2 pcs | F37: 1170
C38: Bubuk Matcha | D38: 10 gr | E38: 1.11 | F38: 166.5
C39: SKM Dairy | D39: 90 gr | E39: 10 gr | F39: 260
C40: Oreo | D40: 52,5 gr | E40: 5,9 gr | F40: 441
C41: Alat Lain | F41: 500
...

Sheet Rekap Penjualan
A1: REKAP USAHA GABINETTE MS
B4: Harga Lama | C4: 8000 | D4: 8000 | E4: 9000 | F4: 9000 | G4: 9000 | H4: 9000 | I4: 10000 | N4: Modal Awal | O4: ='Modal Awal'!F62 -> 1847117 | P4: SIsa BEP | Q4: =O4-Q38 -> 863533
B5: Harga Baru | C5: 9000 | D5: 9000 | E5: 10000 | F5: 10000 | G5: 10000 | H5: 10000 | I5: 10000
B6: Laba | C6: ='Resep Fix'!H19 -> 3395 | D6: ='Resep Fix'!H11 -> 3691.5 | E6: ='Resep Fix'!H26 -> 4417 | F6: ='Resep Fix'!H43 -> 4250.5 | G6: ='Resep Fix'!H35 -> 3443 | H6: ='Resep Fix'!H52 -> 4055 | I6: ='Resep Fix'!H62 -> 4224.9
A7: No | B7: Tanggal | C7: Chocolate | D7: Matcha | E7: Cookies & Cream | F7: Matcha Oreo | G7: Double Choco | H7: Strawberry | I7: Matcha Strawberry | J7: Total | K7: Total Omset | L7: Total Omset | M7: Total Laba | N7: Ket | O7: Hasil | P7: Belanja Batch Selanjutnya | Q7: Hasil Bersih
A8: 1 | B8: 19 Sept 2026 | C8: 3 | D8: 2 | E8: 3 | G8: 2 | I8: 3 | J8: =sum(C8:I8) -> 13 | K8: =(C8*C$4)+(D8*D$4)+(E8*E$4)+(F8*F$4)+(G8*G$4)+(H8*H$4)+(I8*I$4)-18000 -> 97000 | M8: =(C8*C$6)+(D8*D$6)+(E8*E$6)+(F8*F$6)+(G8*G$6)+(H8*H$6)+(I8*I$6) -> 50379.7 | N8: Batch 1 | O8: =(K8+K9+K10+K11) -> 457000 | P8: ='Belanja per Batch'!F17 -> 292500 | Q8: =O8-P8 -> 164500
A9: =A8+1 -> 2 | B9: 20 Sept 2026 | C9: 4 | D9: 5 | E9: 5 | F9: 3 | G9: 2 | H9: 2 | I9: 4 | J9: =sum(C9:I9) -> 25 | K9: =(C9*C$4)+(D9*D$4)+(E9*E$4)+(F9*F$4)+(G9*G$4)+(H9*H$4)+(I9*I$4)-10000 -> 210000 | M9: =(C9*C$6)+(D9*D$6)+(E9*E$6)+(F9*F$6)+(G9*G$6)+(H9*H$6)+(I9*I$6) -> 98769.6 | N9: Batch 2 | O9: =K12+K13+K14+K15 -> 586000 | P9: ='Belanja per Batch'!F31 -> 259623 | Q9: =O9-P9 -> 326377
A10: =A9+1 -> 3 | B10: 21 Sept 2026 | C10: 2 | D10: 2 | E10: 1 | F10: 3 | G10: 2 | H10: 2 | I10: 1 | J10: =sum(C10:I10) -> 13 | K10: =(C10*C$4)+(D10*D$4)+(E10*E$4)+(F10*F$4)+(G10*G$4)+(H10*H$4)+(I10*I$4) -> 114000 | M10: =(C10*C$6)+(D10*D$6)+(E10*E$6)+(F10*F$6)+(G10*G$6)+(H10*H$6)+(I10*I$6) -> 50562.4 | N10: Batch 3 | O10: =K16+K17+K18+K19+K20 -> 369000 | P10: ='Belanja per Batch'!F46 -> 203842 | Q10: =O10-P10 -> 165158
A11: =A10+1 -> 4 | B11: 22 Sept 2026 | F11: 2 | G11: 1 | H11: 1 | J11: =sum(C11:I11) -> 4 | K11: =(C11*C$4)+(D11*D$4)+(E11*E$4)+(F11*F$4)+(G11*G$4)+(H11*H$4)+(I11*I$4) -> 36000 | M11: =(C11*C$6)+(D11*D$6)+(E11*E$6)+(F11*F$6)+(G11*G$6)+(H11*H$6)+(I11*I$6) -> 15999 | N11: Batch 4 | O11: =K21 -> 379000 | P11: ='Belanja per Batch'!F61 -> 155500 | Q11: =O11-P11 -> 223500
A12: =A11+1 -> 5 | B12: 23 Sept 2026 | C12: 6 | E12: 3 | G12: 1 | H12: 3 | J12: =sum(C12:I12) -> 13 | K12: =(C12*C$4)+(D12*D$4)+(E12*E$4)+(F12*F$4)+(G12*G$4)+(H12*H$4)+(I12*I$4) -> 111000 | M12: =(C12*C$6)+(D12*D$6)+(E12*E$6)+(F12*F$6)+(G12*G$6)+(H12*H$6)+(I12*I$6) -> 49229 | N12: Batch 5 | O12: =K22+K23+K24+K25+K26+K27 -> 537000 | P12: ='Belanja per Batch'!F76 -> 120000 | Q12: =O12-P12 -> 417000
A13: =A12+1 -> 6 | B13: 24 Sept 2026 | C13: 3 | E13: 3 | F13: 1 | I13: 4 | J13: =sum(C13:I13) -> 11 | K13: =(C13*C$4)+(D13*D$4)+(E13*E$4)+(F13*F$4)+(G13*G$4)+(H13*H$4)+(I13*I$4) -> 100000 | M13: =(C13*C$6)+(D13*D$6)+(E13*E$6)+(F13*F$6)+(G13*G$6)+(H13*H$6)+(I13*I$6) -> 44586.1 | N13: Batch 6 | O13: =L25+L26+L27 -> 234000 | P13: ='Belanja per Batch'!F102 -> 786418 | Q13: =O13-P13 -> -552418
A14: =A13+1 -> 7 | B14: 26 Sept 2026 | C14: 2 | D14: 1 | E14: 3 | G14: 2 | I14: 2 | J14: =sum(C14:I14) -> 10 | K14: =(C14*C$4)+(D14*D$4)+(E14*E$4)+(F14*F$4)+(G14*G$4)+(H14*H$4)+(I14*I$4) -> 89000 | M14: =(C14*C$6)+(D14*D$6)+(E14*E$6)+(F14*F$6)+(G14*G$6)+(H14*H$6)+(I14*I$6) -> 39068.3 | N14: Batch 7 | O14: =K28+K29+K30+K31 -> 602000 | P14: ='Belanja per Batch'!F120 -> 656533 | Q14: =O14-P14 -> -54533
A15: =A14+1 -> 8 | B15: 27 Sept 2026 | C15: 6 | D15: 7 | F15: 8 | G15: 5 | H15: 5 | I15: 3 | J15: =sum(C15:I15) -> 34 | K15: =(C15*C$4)+(D15*D$4)+(E15*E$4)+(F15*F$4)+(G15*G$4)+(H15*H$4)+(I15*I$4)-10000 -> 286000 | M15: =(C15*C$6)+(D15*D$6)+(E15*E$6)+(F15*F$6)+(G15*G$6)+(H15*H$6)+(I15*I$6) -> 130379.2 | N15: Batch 8 | O15: =L29+L30+L31+K32+K33 -> 294000 | Q15: =O15-P15 -> 294000
A16: =A15+1 -> 9 | B16: 29 Sept 2026 | I16: 1 | J16: =sum(C16:I16) -> 1 | K16: =(C16*C$4)+(D16*D$4)+(E16*E$4)+(F16*F$4)+(G16*G$4)+(H16*H$4)+(I16*I$4) -> 10000 | M16: =(C16*C$6)+(D16*D$6)+(E16*E$6)+(F16*F$6)+(G16*G$6)+(H16*H$6)+(I16*I$6) -> 4224.9 | Q16: =O16-P16 -> 0
A17: =A16+1 -> 10 | B17: 30 Sept 2026 | C17: 5 | D17: 3 | E17: 4 | F17: 1 | H17: 2 | I17: 3 | J17: =sum(C17:I17) -> 18 | K17: =(C17*C$4)+(D17*D$4)+(E17*E$4)+(F17*F$4)+(G17*G$4)+(H17*H$4)+(I17*I$4) -> 157000 | M17: =(C17*C$6)+(D17*D$6)+(E17*E$6)+(F17*F$6)+(G17*G$6)+(H17*H$6)+(I17*I$6) -> 70752.7 | Q17: =O17-P17 -> 0
A18: =A17+1 -> 11 | B18: 46296 | C18: 3 | E18: 1 | F18: 3 | H18: 3 | J18: =sum(C18:I18) -> 10 | K18: =(C18*C$4)+(D18*D$4)+(E18*E$4)+(F18*F$4)+(G18*G$4)+(H18*H$4)+(I18*I$4) -> 87000 | M18: =(C18*C$6)+(D18*D$6)+(E18*E$6)+(F18*F$6)+(G18*G$6)+(H18*H$6)+(I18*I$6) -> 39518.5 | Q18: =O18-P18 -> 0
A19: =A18+1 -> 12 | B19: 46297 | D19: 2 | F19: 1 | H19: 2 | J19: =sum(C19:I19) -> 5 | K19: =(C19*C$4)+(D19*D$4)+(E19*E$4)+(F19*F$4)+(G19*G$4)+(H19*H$4)+(I19*I$4) -> 43000 | M19: =(C19*C$6)+(D19*D$6)+(E19*E$6)+(F19*F$6)+(G19*G$6)+(H19*H$6)+(I19*I$6) -> 19743.5 | Q19: =O19-P19 -> 0
A20: =A19+1 -> 13 | B20: 46298 | E20: 3 | F20: 3 | H20: 2 | J20: =sum(C20:I20) -> 8 | K20: =(C20*C$4)+(D20*D$4)+(E20*E$4)+(F20*F$4)+(G20*G$4)+(H20*H$4)+(I20*I$4) -> 72000 | M20: =(C20*C$6)+(D20*D$6)+(E20*E$6)+(F20*F$6)+(G20*G$6)+(H20*H$6)+(I20*I$6) -> 34112.5 | Q20: =O20-P20 -> 0
A21: =A20+1 -> 14 | B21: 46299 | C21: 8 | D21: 4 | E21: 9 | F21: 1 | G21: 9 | H21: 8 | I21: 5 | J21: =sum(C21:I21) -> 44 | K21: =(C21*C$4)+(D21*D$4)+(E21*E$4)+(F21*F$4)+(G21*G$4)+(H21*H$4)+(I21*I$4)-10000 -> 379000 | M21: =(C21*C$6)+(D21*D$6)+(E21*E$6)+(F21*F$6)+(G21*G$6)+(H21*H$6)+(I21*I$6) -> 170481 | Q21: =O21-P21 -> 0
A22: =A21+1 -> 15 | B22: 46300 | C22: 1 | D22: 1 | E22: 1 | G22: 2 | J22: =sum(C22:I22) -> 5 | K22: =(C22*C$4)+(D22*D$4)+(E22*E$4)+(F22*F$4)+(G22*G$4)+(H22*H$4)+(I22*I$4) -> 43000 | M22: =(C22*C$6)+(D22*D$6)+(E22*E$6)+(F22*F$6)+(G22*G$6)+(H22*H$6)+(I22*I$6) -> 18389.5 | Q22: =O22-P22 -> 0
A23: =A22+1 -> 16 | B23: 46301 | C23: 4 | D23: 2 | E23: 3 | F23: 1 | G23: 2 | H23: 2 | I23: 4 | J23: =sum(C23:I23) -> 18 | K23: =(C23*C$4)+(D23*D$4)+(E23*E$4)+(F23*F$4)+(G23*G$4)+(H23*H$4)+(I23*I$4) -> 160000 | M23: =(C23*C$6)+(D23*D$6)+(E23*E$6)+(F23*F$6)+(G23*G$6)+(H23*H$6)+(I23*I$6) -> 70360.1 | Q23: =O23-P23 -> 0
A24: =A23+1 -> 17 | B24: 46302 | C24: 4 | E24: 4 | F24: 4 | G24: 5 | H24: 3 | I24: 1 | J24: =sum(C24:I24) -> 21 | K24: =(C24*C$4)+(D24*D$4)+(E24*E$4)+(F24*F$4)+(G24*G$4)+(H24*H$4)+(I24*I$4) -> 186000 | M24: =(C24*C$6)+(D24*D$6)+(E24*E$6)+(F24*F$6)+(G24*G$6)+(H24*H$6)+(I24*I$6) -> 81854.9 | Q24: =O24-P24 -> 0
A25: =A24+1 -> 18 | B25: 46303 | C25: 3 | E25: 1 | F25: 1 | G25: 2 | H25: 1 | I25: 2 | J25: =sum(C25:I25) -> 10 | K25: =(E25*E4)+(F25*F4)+(H25*H4)+(I25*I4) -> 47000 | L25: =(C25*C4)+(G25*G4) -> 42000 | M25: =(C25*C$6)+(D25*D$6)+(E25*E$6)+(F25*F$6)+(G25*G$6)+(H25*H$6)+(I25*I$6) -> 38243.3 | Q25: =O25-P25 -> 0
A26: =A25+1 -> 19 | B26: 46304 | D26: 2 | E26: 1 | G26: 2 | H26: 2 | J26: =sum(C26:I26) -> 7 | K26: =(D26*D4)+(H26*H4) -> 34000 | L26: =(E26*E4)+(G26*G4) -> 27000 | M26: =(C26*C$6)+(D26*D$6)+(E26*E$6)+(F26*F$6)+(G26*G$6)+(H26*H$6)+(I26*I$6) -> 26796 | Q26: =O26-P26 -> 0
A27: =A26+1 -> 20 | B27: 46305 | C27: 6 | D27: 2 | E27: 8 | F27: 3 | G27: 5 | H27: 1 | I27: 2 | J27: =sum(C27:I27) -> 27 | K27: =(D27*D4)+(H27*H4)+(I27*I4)-5000+(F27*F4) -> 67000 | L27: =(C27*C4)+(E27*E4)+(G27*G4) -> 165000 | M27: =(C27*C$6)+(D27*D$6)+(E27*E$6)+(F27*F$6)+(G27*G$6)+(H27*H$6)+(I27*I$6) -> 105560.3 | Q27: =O27-P27 -> 0
A28: =A27+1 -> 21 | B28: 46306 | C28: 9 | D28: 6 | E28: 9 | F28: 7 | G28: 5 | H28: 6 | I28: 4 | J28: =sum(C28:I28) -> 46 | K28: =(C28*C$5)+(D28*D$5)+(E28*E$5)+(F28*F$5)+(G28*G$5)+(H28*H$5)+(I28*I$5)-10000 -> 435000 | M28: =(C28*C$6)+(D28*D$6)+(E28*E$6)+(F28*F$6)+(G28*G$6)+(H28*H$6)+(I28*I$6) -> 180655.1 | Q28: =O28-P28 -> 0
A29: =A28+1 -> 22 | B29: 46307 | C29: 4 | D29: 3 | E29: 1 | F29: 1 | I29: 3 | J29: =sum(C29:I29) -> 12 | K29: =(D29*D$5)+(F29*F$5)+(G29*G$5)+(H29*H$5)+(I29*I$5) -> 67000 | L29: =(C29*C$5)+(E29*E$5) -> 46000 | M29: =(C29*C$6)+(D29*D$6)+(F29*F$6)+(G29*G$6)+(H29*H$6)+(I29*I$6) -> 41579.7 | Q29: =O29-P29 -> 0
A30: =A29+1 -> 23 | B30: 46308 | C30: 5 | D30: 1 | E30: 3 | G30: 2 | H30: 1 | I30: 2 | J30: =sum(C30:I30) -> 14 | K30: =(F30*F$5)+(G30*G$5)+(H30*H$5)+(I30*I$5) -> 50000 | L30: =(C30*C5)+(D30*D5)+(E30*E5) -> 84000 | M30: =(C30*C$6)+(D30*D$6)+(E30*E$6)+(F30*F$6)+(G30*G$6)+(H30*H$6)+(I30*I$6) -> 53308.3 | Q30: =O30-P30 -> 0
A31: =A30+1 -> 24 | B31: 46309 | D31: 2 | E31: 2 | F31: 1 | G31: 2 | H31: 2 | J31: =sum(C31:I31) -> 9 | K31: =(F31*F$5)+(G31*G$5)+(H31*H$5) -> 50000 | L31: =(C31*C5)+(D31*D$5)+(E31*E$5)+(I31*I$5) -> 38000 | M31: =(C31*C$6)+(D31*D$6)+(E31*E$6)+(F31*F$6)+(G31*G$6)+(H31*H$6)+(I31*I$6) -> 35463.5 | Q31: =O31-P31 -> 0
A32: =A31+1 -> 25 | B32: 46310 | F32: 1 | G32: 2 | J32: =sum(C32:I32) -> 3 | K32: =(C32*C$5)+(D32*D$5)+(E32*E$5)+(F32*F$5)+(G32*G$5)+(H32*H$5)+(I32*I$5) -> 30000 | M32: =(C32*C$6)+(D32*D$6)+(E32*E$6)+(F32*F$6)+(G32*G$6)+(H32*H$6)+(I32*I$6) -> 11136.5 | Q32: =O32-P32 -> 0
A33: =A32+1 -> 26 | B33: 46311 | C33: 2 | D33: 2 | E33: 2 | H33: 4 | J33: =sum(C33:I33) -> 10 | K33: =(C33*C$5)+(D33*D$5)+(E33*E$5)+(F33*F$5)+(G33*G$5)+(H33*H$5)+(I33*I$5) -> 96000 | M33: =(C33*C$6)+(D33*D$6)+(E33*E$6)+(F33*F$6)+(G33*G$6)+(H33*H$6)+(I33*I$6) -> 39227 | Q33: =O33-P33 -> 0
A34: =A33+1 -> 27 | B34: 46312 | J34: =sum(C34:I34) -> 0 | K34: =(C34*C$4)+(D34*D$4)+(E34*E$4)+(F34*F$4)+(G34*G$4)+(H34*H$4)+(I34*I$4) -> 0 | M34: =(C34*C$6)+(D34*D$6)+(E34*E$6)+(F34*F$6)+(G34*G$6)+(H34*H$6)+(I34*I$6) -> 0 | Q34: =O34-P34 -> 0
A35: =A34+1 -> 28 | B35: 46313 | J35: =sum(C35:I35) -> 0 | K35: =(C35*C$4)+(D35*D$4)+(E35*E$4)+(F35*F$4)+(G35*G$4)+(H35*H$4)+(I35*I$4) -> 0 | M35: =(C35*C$6)+(D35*D$6)+(E35*E$6)+(F35*F$6)+(G35*G$6)+(H35*H$6)+(I35*I$6) -> 0 | Q35: =O35-P35 -> 0
A36: =A35+1 -> 29 | B36: 46314 | J36: =sum(C36:I36) -> 0 | K36: =(C36*C$4)+(D36*D$4)+(E36*E$4)+(F36*F$4)+(G36*G$4)+(H36*H$4)+(I36*I$4) -> 0 | M36: =(C36*C$6)+(D36*D$6)+(E36*E$6)+(F36*F$6)+(G36*G$6)+(H36*H$6)+(I36*I$6) -> 0 | Q36: =O36-P36 -> 0
A37: =A36+1 -> 30 | B37: 46315 | J37: =sum(C37:I37) -> 0 | K37: =(C37*C$4)+(D37*D$4)+(E37*E$4)+(F37*F$4)+(G37*G$4)+(H37*H$4)+(I37*I$4) -> 0 | M37: =(C37*C$6)+(D37*D$6)+(E37*E$6)+(F37*F$6)+(G37*G$6)+(H37*H$6)+(I37*I$6) -> 0 | Q37: =O37-P37 -> 0
A38: TOTAL | C38: =sum(C8:C37) -> 80 | D38: =sum(D8:D37) -> 47 | E38: =sum(E8:E37) -> 70 | F38: =sum(F8:F37) -> 45 | G38: =sum(G8:G37) -> 53 | H38: =sum(H8:H37) -> 52 | I38: =sum(I8:I37) -> 44 | J38: =sum(J8:J37) -> 391 | ... M38: =sum(M8:M37) -> 1520380.6 | O38: =sum(O8:O37) -> 3458000 | P38: =sum(P8:P37) -> 2474416 | Q38: =sum(Q8:Q37) -> 983584
B39: Stock | C39: 7 | D39: 4 | E39: 9 | F39: 8 | G39: 6 | H39: 5 | I39: 9 | J39: =sum(C39:I39) -> 48 | K39: =(C39*C$4)+(D39*D$4)+(E39*E$4)+(F39*F$4)+(G39*G$4)+(H39*H$4)+(I39*I$4) -> 430000
A40: Tester | B40: Batch 1 | F40: 1 | G40: 2 | H40: 4 | I40: 1 | J40: =sum(C40:I40) -> 8 | K40: =(C40*C$4)+(D40*D$4)+(E40*E$4)+(F40*F$4)+(G40*G$4)+(H40*H$4)+(I40*I$4) -> 73000
B41: Batch 2 | C41: 1 | D41: 1 | G41: 1 | H41: 1 | J41: =sum(C41:I41) -> 4 | K41: =(C41*C$4)+(D41*D$4)+(E41*E$4)+(F41*F$4)+(G41*G$4)+(H41*H$4)+(I41*I$4) -> 34000
B42: Batch 3 | C42: 1 | E42: 1 | J42: =sum(C42:I42) -> 2 | K42: =(C42*C$4)+(D42*D$4)+(E42*E$4)+(F42*F$4)+(G42*G$4)+(H42*H$4)+(I42*I$4) -> 17000
...

Sheet Online Market
A1: DATA AKUN MARKET ONLINE
A3: No | B3: Akun | C3: Nama | D3: Email | E3: Password | F3: Nomor
A4: 1 | B4: JakMall | C4: mega septianti | D4: nuvorastore.id@gmail.com | E4: 270116Mega* | F4: 085878847826
A5: =A4+1 -> 2 | B5: Berdu | E5: 270116Mega*
A6: =A5+1 -> 3 | B6: Shopee | C6: megha30 | D6: nuvorastore.id@gmail.com | E6: 270116Mega* | F6: 085162602890
A7: =A6+1 -> 4 | B7: Tokopedia | C7: Nuvorastore id | D7: nuvorastore.id@gmail.com | E7: 270116Mega* | F7: 085878847826
A8: =A7+1 -> 5 | B8: Tik Tok | E8: 270116Mega*
A9: =A8+1 -> 6 | B9: Lazada | E9: 270116Mega*
A10: =A9+1 -> 7 | B10: Meta Ads | E10: 270116Mega*
A11: =A10+1 -> 8 | B11: Facebook | C11: Mega Septianti | D11: nuvorastore.id@gmail.com | E11: 270116Mega*
A12: =A11+1 -> 9 | B12: Instagram | E12: 270116Mega*
A13: =A12+1 -> 10
A14: =A13+1 -> 11
A15: =A14+1 -> 12
A16: =A15+1 -> 13
A17: =A16+1 -> 14
